references/test_kaef_0915.json
{
  "ticker": "KAEF",
  "timestamp": "09:15",
  "prev": 635,
  "open": 660,
  "high": 780,
  "low": 600,
  "ara": 790,
  "arb": 540,
  "avg": 699,
  "val": 1234567,
  "lot": 1765,
  "confidence": 92.5,
  "bid_total": 17075,
  "ask_total": 58282,
  "bids": [
    {"price": 760, "lot": 4004, "freq": 206},
    {"price": 755, "lot": 2891, "freq": 145},
    {"price": 750, "lot": 3245, "freq": 178},
    {"price": 745, "lot": 2156, "freq": 98},
    {"price": 740, "lot": 1879, "freq": 87}
  ],
  "asks": [
    {"price": 790, "lot": 33750, "freq": 1245},
    {"price": 795, "lot": 12456, "freq": 567},
    {"price": 800, "lot": 8901, "freq": 423},
    {"price": 805, "lot": 2175, "freq": 156},
    {"price": 810, "lot": 999, "freq": 78}
  ],
  "expected_bias": "HEAVILY_BEARISH",
  "expected_ratio": 3.41,
  "expected_ask_wall": {"price": 790, "lot": 33750},
  "expected_bid_support": {"price": 760, "lot": 4004}
}
